<sdf version='1.7'>
  <model name='four_bar_linkage'>
    <joint name='world2link0' type='fixed'>
      <pose relative_to='__model__'>0 0 0 0 0 0</pose>
      <parent>world</parent>
      <child>link0</child>
    </joint>
    <link name='link_0'>
      <pose relative_to='world2link0'>0 3 0 0 0 0</pose>
      <visual name='link_0'>
        <pose>0 1.5 0 1.5708 0 0</pose>
        <geometry>
            <cylinder>
              <radius>0.01</radius>
              <length>3.0</length>
            </cylinder>
        </geometry>
      </visual>
    </link>

    <joint name='joint1' type='revolute'>
      <pose relative_to='link0'>0 0 0 0 0 0</pose>
      <parent>link_0</parent>
      <child>link_1</child>
      <axis>
        <xyz>1 0 0</xyz>
      </axis>
    </joint>
    <link name='link_1'>
      <pose relative_to='joint1'>0 0 0 0 0 0</pose>
      <inertial>
        <pose>0 0 0.5 0 -0 0</pose>
        <mass>1</mass>
        <inertia>
          <ixx>0.08333</ixx>
          <ixy>0</ixy>
          <ixz>0</ixz>
          <iyy>0.08333</iyy>
          <iyz>0</iyz>
          <izz>0</izz>
        </inertia>
      </inertial>
      <visual name='link1'>
        <pose>0 0 0.5 0 0 0</pose>
        <geometry>
            <cylinder>
              <radius>0.01</radius>
              <length>1.0</length>
            </cylinder>
        </geometry>
      </visual>
    </link>

    <joint name='joint2' type='revolute'>
      <pose relative_to='link_1'>0 0 1 -1.2175 0 0</pose>
      <parent>link_1</parent>
      <child>link_2</child>
      <axis>
        <xyz>1 0 0</xyz>
      </axis>
    </joint>
    <link name='link_2'>
      <pose relative_to='joint2'>0 0 0 0 0 0</pose>
      <inertial>
        <pose>0 0 2 0 0 0</pose>
        <mass>4</mass>
        <inertia>
          <ixx>5.333</ixx>
          <ixy>0</ixy>
          <ixz>0</ixz>
          <iyy>5.333</iyy>
          <iyz>0</iyz>
          <izz>0</izz>
        </inertia>
      </inertial>
      <visual name='link_2_visual'>
        <pose>0 0 2 0 0 0</pose>
        <geometry>
            <cylinder>
              <radius>0.01</radius>
              <length>4.0</length>
            </cylinder>
        </geometry>
      </visual>
    </link>

    <joint name='joint3' type='revolute'>
      <pose relative_to='link_2'>0 0 4 0.9116 0 0</pose>
      <parent>link_2</parent>
      <child>link_3</child>
      <axis>
        <xyz>1 0 0</xyz>
      </axis>
    </joint>
    <link name='link_3'>
      <pose relative_to='joint3'>0 0 0 0 0 0</pose>
      <inertial>
        <pose>0 0 -1.75 0 0 0</pose>
        <mass>3.5</mass>
        <inertia>
          <ixx>1.30208</ixx>
          <ixy>0</ixy>
          <ixz>0</ixz>
          <iyy>0.30208</iyy>
          <iyz>0</iyz>
          <izz>0</izz>
        </inertia>
      </inertial>
      <visual name='link_3_visual'>
        <pose>0 0 -1.75 0 0 0</pose>
        <geometry>
            <cylinder>
              <radius>0.01</radius>
              <length>3.5</length>
            </cylinder>
        </geometry>
      </visual>
    </link>

    <joint name='closed' type='revolute'>
      <pose relative_to='link_0'>0 3 0 0 0 0</pose>
      <parent>link_3</parent>
      <child>link_0</child>
      <axis>
        <xyz>1 0 0</xyz>
      </axis>
    </joint>
  </model>
</sdf>
