<sdf version='1.7'>
  <model name='four_bar_linkage'>
    <joint name='world2link0' type='fixed'>
      <pose relative_to='__model__'>0 0 0 0 0 0</pose>
      <parent>world</parent>
      <child>link_0</child>
    </joint>
    <link name='link_0'>
      <pose relative_to='world2link0'>0 1.5 0 0 0 0</pose>
      <visual name='link_0_visual'>
        <pose>0 1.5 0 1.5708 0 0</pose>
        <geometry>
            <cylinder>
              <radius>0.01</radius>
              <length>3.0</length>
            </cylinder>
        </geometry>
      </visual>
    </link>
    <joint name='joint1' type='revolute'>
      <pose relative_to='link_0'>0 0 0 0 0 0</pose>
      <parent>link_0</parent>
      <child>link_1</child>
      <axis>
        <xyz>1 0 0</xyz>
        <limit>
          <effort>10000</effort>
          <velocity>0</velocity>
          <lower>-1e+16</lower>
          <upper>1e+16</upper>
        </limit>
        <dynamics>
          <damping>0</damping>
          <friction>0</friction>
          <spring_reference>0</spring_reference>
          <spring_stiffness>0</spring_stiffness>
        </dynamics>
      </axis>
    </joint>
    <link name='link_1'>
      <pose relative_to='joint1'>0 0 0 0 0 0</pose>
      <inertial>
        <pose>0 0 0.5 0 0 0</pose>
        <mass>1</mass>
        <inertia>
          <ixx>0.08333</ixx>
          <ixy>0</ixy>
          <ixz>0</ixz>
          <iyy>0.08333</iyy>
          <iyz>0</iyz>
          <izz>0</izz>
        </inertia>
      </inertial>
      <visual name='link_1_visual'>
        <pose>0 0 0.5 0 0 0</pose>
        <geometry>
            <cylinder>
              <radius>0.01</radius>
              <length>1.0</length>
            </cylinder>
        </geometry>
      </visual>
    </link>
    <joint name='joint2' type='revolute'>
      <pose relative_to='link_1'>0 0 1 -1.2175 0 0</pose>
      <parent>link_1</parent>
      <child>link_2</child>
      <axis>
        <xyz>1 0 0</xyz>
        <limit>
          <effort>10000</effort>
          <velocity>0</velocity>
          <lower>-1e+16</lower>
          <upper>1e+16</upper>
        </limit>
        <dynamics>
          <damping>0</damping>
          <friction>0</friction>
          <spring_reference>0</spring_reference>
          <spring_stiffness>0</spring_stiffness>
        </dynamics>
      </axis>
    </joint>
    <link name='link_2'>
      <pose relative_to='joint2'>0 0 0 0 0 0</pose>
      <inertial>
        <pose>0 0 2 0 0 0</pose>
        <mass>4</mass>
        <inertia>
          <ixx>5.333</ixx>
          <ixy>0</ixy>
          <ixz>0</ixz>
          <iyy>5.333</iyy>
          <iyz>0</iyz>
          <izz>0</izz>
        </inertia>
      </inertial>
      <visual name='link_2_visual'>
        <pose>0 0 2 0 0 0</pose>
        <geometry>
            <cylinder>
              <radius>0.01</radius>
              <length>4.0</length>
            </cylinder>
        </geometry>
      </visual>
    </link>
    <joint name='joint3' type='revolute'>
      <pose relative_to='link_2'>0 0 4 0.9116 0 0</pose>
      <parent>link_2</parent>
      <child>link_3</child>
      <axis>
        <xyz>1 0 0</xyz>
        <limit>
          <effort>10000</effort>
          <velocity>0</velocity>
          <lower>-1e+16</lower>
          <upper>1e+16</upper>
        </limit>
        <dynamics>
          <damping>0</damping>
          <friction>0</friction>
          <spring_reference>0</spring_reference>
          <spring_stiffness>0</spring_stiffness>
        </dynamics>
      </axis>
    </joint>
    <link name='link_3'>
      <pose relative_to='joint3'>0 0 0 0 0 0</pose>
      <inertial>
        <pose>0 0 -1.25 0 0 0</pose>
        <mass>2.5</mass>
        <inertia>
          <ixx>1.30208</ixx>
          <ixy>0</ixy>
          <ixz>0</ixz>
          <iyy>0</iyy>
          <iyz>0</iyz>
          <izz>0</izz>
        </inertia>
      </inertial>
      <visual name='link_3_visual'>
        <pose>0 0 -1.25 0 0 0</pose>
        <geometry>
            <cylinder>
              <radius>0.01</radius>
              <length>2.5</length>
            </cylinder>
        </geometry>
      </visual>
    </link>
    <joint name='closed' type='revolute'>
      <pose relative_to='link_3'>0 0 -2.5 0 0 0</pose>
      <parent>link_3</parent>
      <child>link_0</child>
      <axis>
        <xyz>1 0 0</xyz>
        <limit>
          <effort>10000</effort>
          <velocity>0</velocity>
          <lower>-1e+16</lower>
          <upper>1e+16</upper>
        </limit>
        <dynamics>
          <damping>0</damping>
          <friction>0</friction>
          <spring_reference>0</spring_reference>
          <spring_stiffness>0</spring_stiffness>
        </dynamics>
      </axis>
    </joint>
    <plugin name='joint_state_publisher1' filename='libgazebo_ros_joint_state_publisher.so'>
      <joint_name>joint1</joint_name>
      <joint_name>joint2</joint_name>
      <joint_name>joint3</joint_name>
      <updateRate>100.0</updateRate>
      <alwaysOn>1</alwaysOn>
      <ros>
        <namespace>/joints</namespace>
        <remapping>joint_states:=joint_states_demo</remapping>
      </ros>
    </plugin>
  </model>
</sdf>
